2025-04-18 19:00:36,731 INFO    MainThread:30680 [wandb_setup.py:_flush():67] Current SDK version is 0.19.9
2025-04-18 19:00:36,731 INFO    MainThread:30680 [wandb_setup.py:_flush():67] Configure stats pid to 30680
2025-04-18 19:00:36,731 INFO    MainThread:30680 [wandb_setup.py:_flush():67] Loading settings from C:\Users\DELL\.config\wandb\settings
2025-04-18 19:00:36,731 INFO    MainThread:30680 [wandb_setup.py:_flush():67] Loading settings from C:\Users\DELL\Documents\SEMESTER 8\Deep Learning\Assignment_2\wandb\settings
2025-04-18 19:00:36,732 INFO    MainThread:30680 [wandb_setup.py:_flush():67] Loading settings from environment variables
2025-04-18 19:00:36,732 INFO    MainThread:30680 [wandb_init.py:setup_run_log_directory():662] Logging user logs to C:\Users\DELL\Documents\SEMESTER 8\Deep Learning\Assignment_2\wandb\run-20250418_190036-5xqah2s4\logs\debug.log
2025-04-18 19:00:36,732 INFO    MainThread:30680 [wandb_init.py:setup_run_log_directory():663] Logging internal logs to C:\Users\DELL\Documents\SEMESTER 8\Deep Learning\Assignment_2\wandb\run-20250418_190036-5xqah2s4\logs\debug-internal.log
2025-04-18 19:00:36,732 INFO    MainThread:30680 [wandb_init.py:init():781] calling init triggers
2025-04-18 19:00:36,732 INFO    MainThread:30680 [wandb_init.py:init():786] wandb.init called with sweep_config: {}
config: {'data_dir': 'inaturalist_12K', 'num_filters': 64, 'filter_size': 3, 'filter_organization': 'double', 'activation': 'relu', 'dense_neurons': 256, 'dropout_rate': 0.3, 'batch_norm': True, 'data_augmentation': True, 'learning_rate': 0.001, 'batch_size': 64, 'epochs': 20, '_wandb': {}}
2025-04-18 19:00:36,732 INFO    MainThread:30680 [wandb_init.py:init():809] starting backend
2025-04-18 19:00:36,732 INFO    MainThread:30680 [wandb_init.py:init():813] sending inform_init request
2025-04-18 19:00:36,760 INFO    MainThread:30680 [backend.py:_multiprocessing_setup():101] multiprocessing start_methods=spawn, using: spawn
2025-04-18 19:00:36,761 INFO    MainThread:30680 [wandb_init.py:init():823] backend started and connected
2025-04-18 19:00:36,762 INFO    MainThread:30680 [wandb_init.py:init():915] updated telemetry
2025-04-18 19:00:36,765 INFO    MainThread:30680 [wandb_init.py:init():939] communicating run to backend with 300.0 second timeout
2025-04-18 19:00:37,489 INFO    MainThread:30680 [wandb_init.py:init():1014] starting run threads in backend
2025-04-18 19:00:37,612 INFO    MainThread:30680 [wandb_run.py:_console_start():2454] atexit reg
2025-04-18 19:00:37,612 INFO    MainThread:30680 [wandb_run.py:_redirect():2306] redirect: wrap_raw
2025-04-18 19:00:37,612 INFO    MainThread:30680 [wandb_run.py:_redirect():2371] Wrapping output streams.
2025-04-18 19:00:37,613 INFO    MainThread:30680 [wandb_run.py:_redirect():2394] Redirects installed.
2025-04-18 19:00:37,616 INFO    MainThread:30680 [wandb_init.py:init():1056] run started, returning control to user process
2025-04-18 19:03:19,701 INFO    MsgRouterThr:30680 [mailbox.py:close():129] [no run ID] Closing mailbox, abandoning 1 handles.
2025-04-18 19:03:21,028 ERROR   MainThread:30680 [redirect.py:_on_write():661] [no run ID] error in stderr callback
Traceback (most recent call last):
  File "C:\Users\DELL\anaconda3\envs\CV\lib\site-packages\wandb\sdk\lib\redirect.py", line 659, in _on_write
    cb(written_data)
  File "C:\Users\DELL\anaconda3\envs\CV\lib\site-packages\wandb\sdk\wandb_run.py", line 2381, in <lambda>
    lambda data: self._console_raw_callback("stderr", data),
  File "C:\Users\DELL\anaconda3\envs\CV\lib\site-packages\wandb\sdk\wandb_run.py", line 387, in wrapper
    return func(self, *args, **kwargs)
  File "C:\Users\DELL\anaconda3\envs\CV\lib\site-packages\wandb\sdk\wandb_run.py", line 435, in wrapper_fn
    return func(self, *args, **kwargs)
  File "C:\Users\DELL\anaconda3\envs\CV\lib\site-packages\wandb\sdk\wandb_run.py", line 1518, in _console_raw_callback
    self._backend.interface.publish_output_raw(name, data)
  File "C:\Users\DELL\anaconda3\envs\CV\lib\site-packages\wandb\sdk\interface\interface.py", line 761, in publish_output_raw
    self._publish_output_raw(o)
  File "C:\Users\DELL\anaconda3\envs\CV\lib\site-packages\wandb\sdk\interface\interface_shared.py", line 38, in _publish_output_raw
    self._publish(rec)
  File "C:\Users\DELL\anaconda3\envs\CV\lib\site-packages\wandb\sdk\interface\interface_sock.py", line 39, in _publish
    self._sock_client.send_record_publish(record)
  File "C:\Users\DELL\anaconda3\envs\CV\lib\site-packages\wandb\sdk\lib\sock_client.py", line 174, in send_record_publish
    self.send_server_request(server_req)
  File "C:\Users\DELL\anaconda3\envs\CV\lib\site-packages\wandb\sdk\lib\sock_client.py", line 154, in send_server_request
    self._send_message(msg)
  File "C:\Users\DELL\anaconda3\envs\CV\lib\site-packages\wandb\sdk\lib\sock_client.py", line 151, in _send_message
    self._sendall_with_error_handle(header + data)
  File "C:\Users\DELL\anaconda3\envs\CV\lib\site-packages\wandb\sdk\lib\sock_client.py", line 130, in _sendall_with_error_handle
    sent = self._sock.send(data)
ConnectionAbortedError: [WinError 10053] An established connection was aborted by the software in your host machine
2025-04-18 19:03:21,037 ERROR   MainThread:30680 [redirect.py:_on_write():661] [no run ID] error in stderr callback
Traceback (most recent call last):
  File "C:\Users\DELL\anaconda3\envs\CV\lib\site-packages\wandb\sdk\lib\redirect.py", line 659, in _on_write
    cb(written_data)
  File "C:\Users\DELL\anaconda3\envs\CV\lib\site-packages\wandb\sdk\wandb_run.py", line 2381, in <lambda>
    lambda data: self._console_raw_callback("stderr", data),
  File "C:\Users\DELL\anaconda3\envs\CV\lib\site-packages\wandb\sdk\wandb_run.py", line 387, in wrapper
    return func(self, *args, **kwargs)
  File "C:\Users\DELL\anaconda3\envs\CV\lib\site-packages\wandb\sdk\wandb_run.py", line 435, in wrapper_fn
    return func(self, *args, **kwargs)
  File "C:\Users\DELL\anaconda3\envs\CV\lib\site-packages\wandb\sdk\wandb_run.py", line 1518, in _console_raw_callback
    self._backend.interface.publish_output_raw(name, data)
  File "C:\Users\DELL\anaconda3\envs\CV\lib\site-packages\wandb\sdk\interface\interface.py", line 761, in publish_output_raw
    self._publish_output_raw(o)
  File "C:\Users\DELL\anaconda3\envs\CV\lib\site-packages\wandb\sdk\interface\interface_shared.py", line 38, in _publish_output_raw
    self._publish(rec)
  File "C:\Users\DELL\anaconda3\envs\CV\lib\site-packages\wandb\sdk\interface\interface_sock.py", line 39, in _publish
    self._sock_client.send_record_publish(record)
  File "C:\Users\DELL\anaconda3\envs\CV\lib\site-packages\wandb\sdk\lib\sock_client.py", line 174, in send_record_publish
    self.send_server_request(server_req)
  File "C:\Users\DELL\anaconda3\envs\CV\lib\site-packages\wandb\sdk\lib\sock_client.py", line 154, in send_server_request
    self._send_message(msg)
  File "C:\Users\DELL\anaconda3\envs\CV\lib\site-packages\wandb\sdk\lib\sock_client.py", line 151, in _send_message
    self._sendall_with_error_handle(header + data)
  File "C:\Users\DELL\anaconda3\envs\CV\lib\site-packages\wandb\sdk\lib\sock_client.py", line 130, in _sendall_with_error_handle
    sent = self._sock.send(data)
ConnectionAbortedError: [WinError 10053] An established connection was aborted by the software in your host machine
2025-04-18 19:03:21,040 ERROR   MainThread:30680 [redirect.py:_on_write():661] [no run ID] error in stderr callback
Traceback (most recent call last):
  File "C:\Users\DELL\anaconda3\envs\CV\lib\site-packages\wandb\sdk\lib\redirect.py", line 659, in _on_write
    cb(written_data)
  File "C:\Users\DELL\anaconda3\envs\CV\lib\site-packages\wandb\sdk\wandb_run.py", line 2381, in <lambda>
    lambda data: self._console_raw_callback("stderr", data),
  File "C:\Users\DELL\anaconda3\envs\CV\lib\site-packages\wandb\sdk\wandb_run.py", line 387, in wrapper
    return func(self, *args, **kwargs)
  File "C:\Users\DELL\anaconda3\envs\CV\lib\site-packages\wandb\sdk\wandb_run.py", line 435, in wrapper_fn
    return func(self, *args, **kwargs)
  File "C:\Users\DELL\anaconda3\envs\CV\lib\site-packages\wandb\sdk\wandb_run.py", line 1518, in _console_raw_callback
    self._backend.interface.publish_output_raw(name, data)
  File "C:\Users\DELL\anaconda3\envs\CV\lib\site-packages\wandb\sdk\interface\interface.py", line 761, in publish_output_raw
    self._publish_output_raw(o)
  File "C:\Users\DELL\anaconda3\envs\CV\lib\site-packages\wandb\sdk\interface\interface_shared.py", line 38, in _publish_output_raw
    self._publish(rec)
  File "C:\Users\DELL\anaconda3\envs\CV\lib\site-packages\wandb\sdk\interface\interface_sock.py", line 39, in _publish
    self._sock_client.send_record_publish(record)
  File "C:\Users\DELL\anaconda3\envs\CV\lib\site-packages\wandb\sdk\lib\sock_client.py", line 174, in send_record_publish
    self.send_server_request(server_req)
  File "C:\Users\DELL\anaconda3\envs\CV\lib\site-packages\wandb\sdk\lib\sock_client.py", line 154, in send_server_request
    self._send_message(msg)
  File "C:\Users\DELL\anaconda3\envs\CV\lib\site-packages\wandb\sdk\lib\sock_client.py", line 151, in _send_message
    self._sendall_with_error_handle(header + data)
  File "C:\Users\DELL\anaconda3\envs\CV\lib\site-packages\wandb\sdk\lib\sock_client.py", line 130, in _sendall_with_error_handle
    sent = self._sock.send(data)
ConnectionAbortedError: [WinError 10053] An established connection was aborted by the software in your host machine
2025-04-18 19:03:21,041 ERROR   MainThread:30680 [redirect.py:_on_write():661] [no run ID] error in stderr callback
Traceback (most recent call last):
  File "C:\Users\DELL\anaconda3\envs\CV\lib\site-packages\wandb\sdk\lib\redirect.py", line 659, in _on_write
    cb(written_data)
  File "C:\Users\DELL\anaconda3\envs\CV\lib\site-packages\wandb\sdk\wandb_run.py", line 2381, in <lambda>
    lambda data: self._console_raw_callback("stderr", data),
  File "C:\Users\DELL\anaconda3\envs\CV\lib\site-packages\wandb\sdk\wandb_run.py", line 387, in wrapper
    return func(self, *args, **kwargs)
  File "C:\Users\DELL\anaconda3\envs\CV\lib\site-packages\wandb\sdk\wandb_run.py", line 435, in wrapper_fn
    return func(self, *args, **kwargs)
  File "C:\Users\DELL\anaconda3\envs\CV\lib\site-packages\wandb\sdk\wandb_run.py", line 1518, in _console_raw_callback
    self._backend.interface.publish_output_raw(name, data)
  File "C:\Users\DELL\anaconda3\envs\CV\lib\site-packages\wandb\sdk\interface\interface.py", line 761, in publish_output_raw
    self._publish_output_raw(o)
  File "C:\Users\DELL\anaconda3\envs\CV\lib\site-packages\wandb\sdk\interface\interface_shared.py", line 38, in _publish_output_raw
    self._publish(rec)
  File "C:\Users\DELL\anaconda3\envs\CV\lib\site-packages\wandb\sdk\interface\interface_sock.py", line 39, in _publish
    self._sock_client.send_record_publish(record)
  File "C:\Users\DELL\anaconda3\envs\CV\lib\site-packages\wandb\sdk\lib\sock_client.py", line 174, in send_record_publish
    self.send_server_request(server_req)
  File "C:\Users\DELL\anaconda3\envs\CV\lib\site-packages\wandb\sdk\lib\sock_client.py", line 154, in send_server_request
    self._send_message(msg)
  File "C:\Users\DELL\anaconda3\envs\CV\lib\site-packages\wandb\sdk\lib\sock_client.py", line 151, in _send_message
    self._sendall_with_error_handle(header + data)
  File "C:\Users\DELL\anaconda3\envs\CV\lib\site-packages\wandb\sdk\lib\sock_client.py", line 130, in _sendall_with_error_handle
    sent = self._sock.send(data)
ConnectionAbortedError: [WinError 10053] An established connection was aborted by the software in your host machine
2025-04-18 19:03:21,042 ERROR   MainThread:30680 [redirect.py:_on_write():661] [no run ID] error in stderr callback
Traceback (most recent call last):
  File "C:\Users\DELL\anaconda3\envs\CV\lib\site-packages\wandb\sdk\lib\redirect.py", line 659, in _on_write
    cb(written_data)
  File "C:\Users\DELL\anaconda3\envs\CV\lib\site-packages\wandb\sdk\wandb_run.py", line 2381, in <lambda>
    lambda data: self._console_raw_callback("stderr", data),
  File "C:\Users\DELL\anaconda3\envs\CV\lib\site-packages\wandb\sdk\wandb_run.py", line 387, in wrapper
    return func(self, *args, **kwargs)
  File "C:\Users\DELL\anaconda3\envs\CV\lib\site-packages\wandb\sdk\wandb_run.py", line 435, in wrapper_fn
    return func(self, *args, **kwargs)
  File "C:\Users\DELL\anaconda3\envs\CV\lib\site-packages\wandb\sdk\wandb_run.py", line 1518, in _console_raw_callback
    self._backend.interface.publish_output_raw(name, data)
  File "C:\Users\DELL\anaconda3\envs\CV\lib\site-packages\wandb\sdk\interface\interface.py", line 761, in publish_output_raw
    self._publish_output_raw(o)
  File "C:\Users\DELL\anaconda3\envs\CV\lib\site-packages\wandb\sdk\interface\interface_shared.py", line 38, in _publish_output_raw
    self._publish(rec)
  File "C:\Users\DELL\anaconda3\envs\CV\lib\site-packages\wandb\sdk\interface\interface_sock.py", line 39, in _publish
    self._sock_client.send_record_publish(record)
  File "C:\Users\DELL\anaconda3\envs\CV\lib\site-packages\wandb\sdk\lib\sock_client.py", line 174, in send_record_publish
    self.send_server_request(server_req)
  File "C:\Users\DELL\anaconda3\envs\CV\lib\site-packages\wandb\sdk\lib\sock_client.py", line 154, in send_server_request
    self._send_message(msg)
  File "C:\Users\DELL\anaconda3\envs\CV\lib\site-packages\wandb\sdk\lib\sock_client.py", line 151, in _send_message
    self._sendall_with_error_handle(header + data)
  File "C:\Users\DELL\anaconda3\envs\CV\lib\site-packages\wandb\sdk\lib\sock_client.py", line 130, in _sendall_with_error_handle
    sent = self._sock.send(data)
ConnectionAbortedError: [WinError 10053] An established connection was aborted by the software in your host machine
2025-04-18 19:03:21,043 ERROR   MainThread:30680 [redirect.py:_on_write():661] [no run ID] error in stderr callback
Traceback (most recent call last):
  File "C:\Users\DELL\anaconda3\envs\CV\lib\site-packages\wandb\sdk\lib\redirect.py", line 659, in _on_write
    cb(written_data)
  File "C:\Users\DELL\anaconda3\envs\CV\lib\site-packages\wandb\sdk\wandb_run.py", line 2381, in <lambda>
    lambda data: self._console_raw_callback("stderr", data),
  File "C:\Users\DELL\anaconda3\envs\CV\lib\site-packages\wandb\sdk\wandb_run.py", line 387, in wrapper
    return func(self, *args, **kwargs)
  File "C:\Users\DELL\anaconda3\envs\CV\lib\site-packages\wandb\sdk\wandb_run.py", line 435, in wrapper_fn
    return func(self, *args, **kwargs)
  File "C:\Users\DELL\anaconda3\envs\CV\lib\site-packages\wandb\sdk\wandb_run.py", line 1518, in _console_raw_callback
    self._backend.interface.publish_output_raw(name, data)
  File "C:\Users\DELL\anaconda3\envs\CV\lib\site-packages\wandb\sdk\interface\interface.py", line 761, in publish_output_raw
    self._publish_output_raw(o)
  File "C:\Users\DELL\anaconda3\envs\CV\lib\site-packages\wandb\sdk\interface\interface_shared.py", line 38, in _publish_output_raw
    self._publish(rec)
  File "C:\Users\DELL\anaconda3\envs\CV\lib\site-packages\wandb\sdk\interface\interface_sock.py", line 39, in _publish
    self._sock_client.send_record_publish(record)
  File "C:\Users\DELL\anaconda3\envs\CV\lib\site-packages\wandb\sdk\lib\sock_client.py", line 174, in send_record_publish
    self.send_server_request(server_req)
  File "C:\Users\DELL\anaconda3\envs\CV\lib\site-packages\wandb\sdk\lib\sock_client.py", line 154, in send_server_request
    self._send_message(msg)
  File "C:\Users\DELL\anaconda3\envs\CV\lib\site-packages\wandb\sdk\lib\sock_client.py", line 151, in _send_message
    self._sendall_with_error_handle(header + data)
  File "C:\Users\DELL\anaconda3\envs\CV\lib\site-packages\wandb\sdk\lib\sock_client.py", line 130, in _sendall_with_error_handle
    sent = self._sock.send(data)
ConnectionAbortedError: [WinError 10053] An established connection was aborted by the software in your host machine
2025-04-18 19:03:21,045 ERROR   MainThread:30680 [redirect.py:_on_write():661] [no run ID] error in stderr callback
Traceback (most recent call last):
  File "C:\Users\DELL\anaconda3\envs\CV\lib\site-packages\wandb\sdk\lib\redirect.py", line 659, in _on_write
    cb(written_data)
  File "C:\Users\DELL\anaconda3\envs\CV\lib\site-packages\wandb\sdk\wandb_run.py", line 2381, in <lambda>
    lambda data: self._console_raw_callback("stderr", data),
  File "C:\Users\DELL\anaconda3\envs\CV\lib\site-packages\wandb\sdk\wandb_run.py", line 387, in wrapper
    return func(self, *args, **kwargs)
  File "C:\Users\DELL\anaconda3\envs\CV\lib\site-packages\wandb\sdk\wandb_run.py", line 435, in wrapper_fn
    return func(self, *args, **kwargs)
  File "C:\Users\DELL\anaconda3\envs\CV\lib\site-packages\wandb\sdk\wandb_run.py", line 1518, in _console_raw_callback
    self._backend.interface.publish_output_raw(name, data)
  File "C:\Users\DELL\anaconda3\envs\CV\lib\site-packages\wandb\sdk\interface\interface.py", line 761, in publish_output_raw
    self._publish_output_raw(o)
  File "C:\Users\DELL\anaconda3\envs\CV\lib\site-packages\wandb\sdk\interface\interface_shared.py", line 38, in _publish_output_raw
    self._publish(rec)
  File "C:\Users\DELL\anaconda3\envs\CV\lib\site-packages\wandb\sdk\interface\interface_sock.py", line 39, in _publish
    self._sock_client.send_record_publish(record)
  File "C:\Users\DELL\anaconda3\envs\CV\lib\site-packages\wandb\sdk\lib\sock_client.py", line 174, in send_record_publish
    self.send_server_request(server_req)
  File "C:\Users\DELL\anaconda3\envs\CV\lib\site-packages\wandb\sdk\lib\sock_client.py", line 154, in send_server_request
    self._send_message(msg)
  File "C:\Users\DELL\anaconda3\envs\CV\lib\site-packages\wandb\sdk\lib\sock_client.py", line 151, in _send_message
    self._sendall_with_error_handle(header + data)
  File "C:\Users\DELL\anaconda3\envs\CV\lib\site-packages\wandb\sdk\lib\sock_client.py", line 130, in _sendall_with_error_handle
    sent = self._sock.send(data)
ConnectionAbortedError: [WinError 10053] An established connection was aborted by the software in your host machine
2025-04-18 19:03:21,046 ERROR   MainThread:30680 [redirect.py:_on_write():661] [no run ID] error in stderr callback
Traceback (most recent call last):
  File "C:\Users\DELL\anaconda3\envs\CV\lib\site-packages\wandb\sdk\lib\redirect.py", line 659, in _on_write
    cb(written_data)
  File "C:\Users\DELL\anaconda3\envs\CV\lib\site-packages\wandb\sdk\wandb_run.py", line 2381, in <lambda>
    lambda data: self._console_raw_callback("stderr", data),
  File "C:\Users\DELL\anaconda3\envs\CV\lib\site-packages\wandb\sdk\wandb_run.py", line 387, in wrapper
    return func(self, *args, **kwargs)
  File "C:\Users\DELL\anaconda3\envs\CV\lib\site-packages\wandb\sdk\wandb_run.py", line 435, in wrapper_fn
    return func(self, *args, **kwargs)
  File "C:\Users\DELL\anaconda3\envs\CV\lib\site-packages\wandb\sdk\wandb_run.py", line 1518, in _console_raw_callback
    self._backend.interface.publish_output_raw(name, data)
  File "C:\Users\DELL\anaconda3\envs\CV\lib\site-packages\wandb\sdk\interface\interface.py", line 761, in publish_output_raw
    self._publish_output_raw(o)
  File "C:\Users\DELL\anaconda3\envs\CV\lib\site-packages\wandb\sdk\interface\interface_shared.py", line 38, in _publish_output_raw
    self._publish(rec)
  File "C:\Users\DELL\anaconda3\envs\CV\lib\site-packages\wandb\sdk\interface\interface_sock.py", line 39, in _publish
    self._sock_client.send_record_publish(record)
  File "C:\Users\DELL\anaconda3\envs\CV\lib\site-packages\wandb\sdk\lib\sock_client.py", line 174, in send_record_publish
    self.send_server_request(server_req)
  File "C:\Users\DELL\anaconda3\envs\CV\lib\site-packages\wandb\sdk\lib\sock_client.py", line 154, in send_server_request
    self._send_message(msg)
  File "C:\Users\DELL\anaconda3\envs\CV\lib\site-packages\wandb\sdk\lib\sock_client.py", line 151, in _send_message
    self._sendall_with_error_handle(header + data)
  File "C:\Users\DELL\anaconda3\envs\CV\lib\site-packages\wandb\sdk\lib\sock_client.py", line 130, in _sendall_with_error_handle
    sent = self._sock.send(data)
ConnectionAbortedError: [WinError 10053] An established connection was aborted by the software in your host machine
2025-04-18 19:03:21,047 ERROR   MainThread:30680 [redirect.py:_on_write():661] [no run ID] error in stderr callback
Traceback (most recent call last):
  File "C:\Users\DELL\anaconda3\envs\CV\lib\site-packages\wandb\sdk\lib\redirect.py", line 659, in _on_write
    cb(written_data)
  File "C:\Users\DELL\anaconda3\envs\CV\lib\site-packages\wandb\sdk\wandb_run.py", line 2381, in <lambda>
    lambda data: self._console_raw_callback("stderr", data),
  File "C:\Users\DELL\anaconda3\envs\CV\lib\site-packages\wandb\sdk\wandb_run.py", line 387, in wrapper
    return func(self, *args, **kwargs)
  File "C:\Users\DELL\anaconda3\envs\CV\lib\site-packages\wandb\sdk\wandb_run.py", line 435, in wrapper_fn
    return func(self, *args, **kwargs)
  File "C:\Users\DELL\anaconda3\envs\CV\lib\site-packages\wandb\sdk\wandb_run.py", line 1518, in _console_raw_callback
    self._backend.interface.publish_output_raw(name, data)
  File "C:\Users\DELL\anaconda3\envs\CV\lib\site-packages\wandb\sdk\interface\interface.py", line 761, in publish_output_raw
    self._publish_output_raw(o)
  File "C:\Users\DELL\anaconda3\envs\CV\lib\site-packages\wandb\sdk\interface\interface_shared.py", line 38, in _publish_output_raw
    self._publish(rec)
  File "C:\Users\DELL\anaconda3\envs\CV\lib\site-packages\wandb\sdk\interface\interface_sock.py", line 39, in _publish
    self._sock_client.send_record_publish(record)
  File "C:\Users\DELL\anaconda3\envs\CV\lib\site-packages\wandb\sdk\lib\sock_client.py", line 174, in send_record_publish
    self.send_server_request(server_req)
  File "C:\Users\DELL\anaconda3\envs\CV\lib\site-packages\wandb\sdk\lib\sock_client.py", line 154, in send_server_request
    self._send_message(msg)
  File "C:\Users\DELL\anaconda3\envs\CV\lib\site-packages\wandb\sdk\lib\sock_client.py", line 151, in _send_message
    self._sendall_with_error_handle(header + data)
  File "C:\Users\DELL\anaconda3\envs\CV\lib\site-packages\wandb\sdk\lib\sock_client.py", line 130, in _sendall_with_error_handle
    sent = self._sock.send(data)
ConnectionAbortedError: [WinError 10053] An established connection was aborted by the software in your host machine
2025-04-18 19:03:21,048 ERROR   MainThread:30680 [redirect.py:_on_write():661] [no run ID] error in stderr callback
Traceback (most recent call last):
  File "C:\Users\DELL\anaconda3\envs\CV\lib\site-packages\wandb\sdk\lib\redirect.py", line 659, in _on_write
    cb(written_data)
  File "C:\Users\DELL\anaconda3\envs\CV\lib\site-packages\wandb\sdk\wandb_run.py", line 2381, in <lambda>
    lambda data: self._console_raw_callback("stderr", data),
  File "C:\Users\DELL\anaconda3\envs\CV\lib\site-packages\wandb\sdk\wandb_run.py", line 387, in wrapper
    return func(self, *args, **kwargs)
  File "C:\Users\DELL\anaconda3\envs\CV\lib\site-packages\wandb\sdk\wandb_run.py", line 435, in wrapper_fn
    return func(self, *args, **kwargs)
  File "C:\Users\DELL\anaconda3\envs\CV\lib\site-packages\wandb\sdk\wandb_run.py", line 1518, in _console_raw_callback
    self._backend.interface.publish_output_raw(name, data)
  File "C:\Users\DELL\anaconda3\envs\CV\lib\site-packages\wandb\sdk\interface\interface.py", line 761, in publish_output_raw
    self._publish_output_raw(o)
  File "C:\Users\DELL\anaconda3\envs\CV\lib\site-packages\wandb\sdk\interface\interface_shared.py", line 38, in _publish_output_raw
    self._publish(rec)
  File "C:\Users\DELL\anaconda3\envs\CV\lib\site-packages\wandb\sdk\interface\interface_sock.py", line 39, in _publish
    self._sock_client.send_record_publish(record)
  File "C:\Users\DELL\anaconda3\envs\CV\lib\site-packages\wandb\sdk\lib\sock_client.py", line 174, in send_record_publish
    self.send_server_request(server_req)
  File "C:\Users\DELL\anaconda3\envs\CV\lib\site-packages\wandb\sdk\lib\sock_client.py", line 154, in send_server_request
    self._send_message(msg)
  File "C:\Users\DELL\anaconda3\envs\CV\lib\site-packages\wandb\sdk\lib\sock_client.py", line 151, in _send_message
    self._sendall_with_error_handle(header + data)
  File "C:\Users\DELL\anaconda3\envs\CV\lib\site-packages\wandb\sdk\lib\sock_client.py", line 130, in _sendall_with_error_handle
    sent = self._sock.send(data)
ConnectionAbortedError: [WinError 10053] An established connection was aborted by the software in your host machine
2025-04-18 19:03:21,048 ERROR   MainThread:30680 [redirect.py:_on_write():661] [no run ID] error in stderr callback
Traceback (most recent call last):
  File "C:\Users\DELL\anaconda3\envs\CV\lib\site-packages\wandb\sdk\lib\redirect.py", line 659, in _on_write
    cb(written_data)
  File "C:\Users\DELL\anaconda3\envs\CV\lib\site-packages\wandb\sdk\wandb_run.py", line 2381, in <lambda>
    lambda data: self._console_raw_callback("stderr", data),
  File "C:\Users\DELL\anaconda3\envs\CV\lib\site-packages\wandb\sdk\wandb_run.py", line 387, in wrapper
    return func(self, *args, **kwargs)
  File "C:\Users\DELL\anaconda3\envs\CV\lib\site-packages\wandb\sdk\wandb_run.py", line 435, in wrapper_fn
    return func(self, *args, **kwargs)
  File "C:\Users\DELL\anaconda3\envs\CV\lib\site-packages\wandb\sdk\wandb_run.py", line 1518, in _console_raw_callback
    self._backend.interface.publish_output_raw(name, data)
  File "C:\Users\DELL\anaconda3\envs\CV\lib\site-packages\wandb\sdk\interface\interface.py", line 761, in publish_output_raw
    self._publish_output_raw(o)
  File "C:\Users\DELL\anaconda3\envs\CV\lib\site-packages\wandb\sdk\interface\interface_shared.py", line 38, in _publish_output_raw
    self._publish(rec)
  File "C:\Users\DELL\anaconda3\envs\CV\lib\site-packages\wandb\sdk\interface\interface_sock.py", line 39, in _publish
    self._sock_client.send_record_publish(record)
  File "C:\Users\DELL\anaconda3\envs\CV\lib\site-packages\wandb\sdk\lib\sock_client.py", line 174, in send_record_publish
    self.send_server_request(server_req)
  File "C:\Users\DELL\anaconda3\envs\CV\lib\site-packages\wandb\sdk\lib\sock_client.py", line 154, in send_server_request
    self._send_message(msg)
  File "C:\Users\DELL\anaconda3\envs\CV\lib\site-packages\wandb\sdk\lib\sock_client.py", line 151, in _send_message
    self._sendall_with_error_handle(header + data)
  File "C:\Users\DELL\anaconda3\envs\CV\lib\site-packages\wandb\sdk\lib\sock_client.py", line 130, in _sendall_with_error_handle
    sent = self._sock.send(data)
ConnectionAbortedError: [WinError 10053] An established connection was aborted by the software in your host machine
2025-04-18 19:03:21,049 ERROR   MainThread:30680 [redirect.py:_on_write():661] [no run ID] error in stderr callback
Traceback (most recent call last):
  File "C:\Users\DELL\anaconda3\envs\CV\lib\site-packages\wandb\sdk\lib\redirect.py", line 659, in _on_write
    cb(written_data)
  File "C:\Users\DELL\anaconda3\envs\CV\lib\site-packages\wandb\sdk\wandb_run.py", line 2381, in <lambda>
    lambda data: self._console_raw_callback("stderr", data),
  File "C:\Users\DELL\anaconda3\envs\CV\lib\site-packages\wandb\sdk\wandb_run.py", line 387, in wrapper
    return func(self, *args, **kwargs)
  File "C:\Users\DELL\anaconda3\envs\CV\lib\site-packages\wandb\sdk\wandb_run.py", line 435, in wrapper_fn
    return func(self, *args, **kwargs)
  File "C:\Users\DELL\anaconda3\envs\CV\lib\site-packages\wandb\sdk\wandb_run.py", line 1518, in _console_raw_callback
    self._backend.interface.publish_output_raw(name, data)
  File "C:\Users\DELL\anaconda3\envs\CV\lib\site-packages\wandb\sdk\interface\interface.py", line 761, in publish_output_raw
    self._publish_output_raw(o)
  File "C:\Users\DELL\anaconda3\envs\CV\lib\site-packages\wandb\sdk\interface\interface_shared.py", line 38, in _publish_output_raw
    self._publish(rec)
  File "C:\Users\DELL\anaconda3\envs\CV\lib\site-packages\wandb\sdk\interface\interface_sock.py", line 39, in _publish
    self._sock_client.send_record_publish(record)
  File "C:\Users\DELL\anaconda3\envs\CV\lib\site-packages\wandb\sdk\lib\sock_client.py", line 174, in send_record_publish
    self.send_server_request(server_req)
  File "C:\Users\DELL\anaconda3\envs\CV\lib\site-packages\wandb\sdk\lib\sock_client.py", line 154, in send_server_request
    self._send_message(msg)
  File "C:\Users\DELL\anaconda3\envs\CV\lib\site-packages\wandb\sdk\lib\sock_client.py", line 151, in _send_message
    self._sendall_with_error_handle(header + data)
  File "C:\Users\DELL\anaconda3\envs\CV\lib\site-packages\wandb\sdk\lib\sock_client.py", line 130, in _sendall_with_error_handle
    sent = self._sock.send(data)
ConnectionAbortedError: [WinError 10053] An established connection was aborted by the software in your host machine
